<?xml version="1.0"?>

<robot name="YTR_04_A" xmlns:xacro="http://www.ros.org/wiki/xacro">

  <xacro:property name="wheelbase" value="0" />
  <xacro:property name="axelwidth" value="0" />

  <xacro:include filename="$(find autonomousim_description)/urdf/materials.xml"/>
  <xacro:include filename="$(find autonomousim_description)/urdf/inertias.xml"/>
  <xacro:include filename="$(find autonomousim_description)/sensors/zed.xml"/>
  <xacro:include filename="$(find autonomousim_description)/sensors/hokuyo_utm30lx.xml"/>
  <xacro:include filename="$(find autonomousim_description)/sensors/imu.xml"/>

                      <!--base description-->

  <link name="base_footprint">
    <visual>
      <origin rpy="0 0 0" xyz="0 0 0"/>
      <geometry>
        <box size="0.001 0.001 0.001"/>
      </geometry>
    </visual>
  </link>

  <joint name="base_footprint_joint" type="fixed">
    <origin rpy="0 0 0" xyz="0 0 0"/>
    <parent link="base_footprint"/>
    <child link="base_link"/>
  </joint>

  <link name="base_link">
    <visual>
      <geometry>
        <mesh filename="package://autonomousim_description/meshes/chassis.stl" scale = "0.001 0.001 0.001" />
      </geometry>
      <material name="white"/>
    </visual>
    <collision>
      <geometry>
        <mesh filename="package://autonomousim_description/meshes/chassis.stl" scale = "0.001 0.001 0.001"   />
      </geometry>
    </collision>
    <xacro:chassis_inertial_params/>
  </link>

    <gazebo reference="base_link">
      <material>Gazebo/Carbone</material>
      <turnGravityOff>false</turnGravityOff>
    </gazebo>
    
                      <!--left upright description-->

    <link name="front_left_upright">
      <inertial>
        <mass value="1.0" />
        <origin xyz="0 0 0" /> 
        <inertia  ixx="1.0" ixy="0.0"  ixz="0.0"  iyy="1.0"  iyz="0.0"  izz="1.0" />
      </inertial>
      <visual>
        <origin xyz="0 0 0" rpy="0 0 0" />
        <geometry>
          <box size="0.01 0.01 0.01" />
        </geometry>
      </visual>
      <collision>
        <origin xyz="0 0 0" rpy="0 0 0" />
        <geometry>
          <box size="0.01 0.01 0.01" />
        </geometry>
      </collision>
    </link>

    <joint name="left_steering_joint" type="revolute" >
      <limit lower="-0.785398163" upper="0.785398163" effort="100000" velocity="25" />
      <axis xyz="0 0 1" />
      <parent link="base_link" />
      <child link="front_left_upright" />
      <origin xyz="0 0.6 0.232" rpy="0 0 0" />
    </joint>
 
  <transmission name="front_left_upright_trans">
    <type>transmission_interface/SimpleTransmission</type>
    <joint name="left_steering_joint">
      <hardwareInterface>hardware_interface/EffortJointInterface</hardwareInterface>
    </joint>
    <actuator name="front_left_upright_act">
      <hardwareInterface>hardware_interface/EffortJointInterface</hardwareInterface>
      <mechanicalReduction>1</mechanicalReduction>
    </actuator>
  </transmission>

    <gazebo reference="front_left_upright">
      <material>Gazebo/Black</material>
      <turnGravityOff>false</turnGravityOff>
    </gazebo>

                         <!--left upright description-->

    <link name="front_right_upright">
      <inertial>
        <mass value="1.0" />
        <origin xyz="0 0 0" /> 
        <inertia  ixx="1.0" ixy="0.0"  ixz="0.0"  iyy="1.0"  iyz="0.0"  izz="1.0" />
      </inertial>
      <visual>
        <origin xyz="0 0 0" rpy="0 0 0" />
        <geometry>
          <box size="0.01 0.01 0.01" />
        </geometry>
      </visual>
      <collision>
        <origin xyz="0 0 0" rpy="0 0 0" />
        <geometry>
          <box size="0.01 0.01 0.01" />
        </geometry>
      </collision>
    </link>

    <joint name="right_steering_joint" type="revolute" >
      <limit lower="-0.785398163" upper="0.785398163" effort="100000" velocity="25" />
      <axis xyz="0 0 1" />
      <parent link="base_link" />
      <child link="front_right_upright" />
      <origin xyz="0 -0.6 0.232" rpy="0 0 0" />
    </joint>

  <transmission name="front_right_upright_trans">
    <type>transmission_interface/SimpleTransmission</type>
    <joint name="right_steering_joint">
      <hardwareInterface>hardware_interface/EffortJointInterface</hardwareInterface>
    </joint>
    <actuator name="front_right_upright_act">
      <hardwareInterface>hardware_interface/EffortJointInterface</hardwareInterface>
      <mechanicalReduction>1</mechanicalReduction>
    </actuator>
  </transmission>

    <gazebo reference="front_right_upright">
      <material>Gazebo/Black</material>
      <turnGravityOff>false</turnGravityOff>
    </gazebo>

                        <!--right wheel description-->

  <link name="front_right_wheel_link">
    <visual>
     <origin xyz="0 0 0" rpy="0 0 0" />
      <geometry>
        <mesh filename="package://autonomousim_description/meshes/wheel.stl"/>
      </geometry>
      <material name="black"/>
    </visual>
    <collision>
     <origin xyz="0 0 0" rpy="0 0 0" />
      <geometry>
        <mesh filename="package://autonomousim_description/meshes/wheel.stl"/>
      </geometry>
      <surface>
        <friction>
          <ode>
            <mu>100</mu>
            <mu2>50</mu2>
          </ode>
        </friction>
      </surface>
    </collision>
    <xacro:wheels_inertia/>
  </link>

    <joint name="right_front_axle" type="continuous" >
      <axis xyz="0 -1 0" />
      <parent link="front_right_upright" />
      <child link="front_right_wheel_link" />
      <origin xyz="0 0 0" rpy="0 0 0" />
      <limit effort="120" velocity="170"/>
    </joint>

  <transmission name="right_front_axle_trans">
    <type>transmission_interface/SimpleTransmission</type>
    <joint name="right_front_axle">
      <hardwareInterface>hardware_interface/VelocityJointInterface</hardwareInterface>
    </joint>
    <actuator name="right_front_axle_act">
      <hardwareInterface>hardware_interface/VelocityJointInterface</hardwareInterface>
      <mechanicalReduction>1</mechanicalReduction>
    </actuator>
  </transmission>

    <gazebo reference="front_right_wheel_link">
      <material>Gazebo/Black</material>
      <turnGravityOff>false</turnGravityOff>
    </gazebo>

                        <!--right wheel description-->

  <link name="front_left_wheel_link">
    <visual>
     <origin xyz="0 0 0" rpy="0 0 0" />
      <geometry>
        <mesh filename="package://autonomousim_description/meshes/wheel.stl"/>
      </geometry>
      <material name="black"/>
    </visual>
    <collision>
     <origin xyz="0 0 0" rpy="0 0 0" />
      <geometry>
        <mesh filename="package://autonomousim_description/meshes/wheel.stl"/>
      </geometry>
      <surface>
        <friction>
          <ode>
            <mu>100</mu>
            <mu2>50</mu2>
          </ode>
        </friction>
      </surface>
    </collision>
    <xacro:wheels_inertia/>
  </link>

    <joint name="left_front_axle" type="continuous" >
      <axis xyz="0 -1 0" />
      <parent link="front_left_upright" />
      <child link="front_left_wheel_link" />
      <origin xyz="0 0 0" rpy="0 0 0" />
      <limit effort="120" velocity="170"/>
    </joint>

  <transmission name="left_front_axle_trans">
    <type>transmission_interface/SimpleTransmission</type>
    <joint name="left_front_axle">
      <hardwareInterface>hardware_interface/VelocityJointInterface</hardwareInterface>
    </joint>
    <actuator name="left_front_axle_act">
      <hardwareInterface>hardware_interface/VelocityJointInterface</hardwareInterface>
      <mechanicalReduction>1</mechanicalReduction>
    </actuator>
  </transmission>

    <gazebo reference="front_left_wheel_link">
      <material>Gazebo/Black</material>
      <turnGravityOff>false</turnGravityOff>
    </gazebo>

                        <!--rear wheel description-->


  <link name="rear_right_wheel_link">
    <visual>
     <origin xyz="0 0 0" rpy="0 0 0" />
      <geometry>
        <mesh filename="package://autonomousim_description/meshes/wheel.stl"/>
      </geometry>
      <material name="black"/>
    </visual>
    <collision>
     <origin xyz="0 0 0" rpy="0 0 0" />
      <geometry>
        <mesh filename="package://autonomousim_description/meshes/wheel.stl"/>
      </geometry>
      <surface>
        <friction>
          <ode>
            <mu>100</mu>
            <mu2>50</mu2>
          </ode>
        </friction>
      </surface>
    </collision>
    <xacro:wheels_inertia/>
  </link>

<joint name="right_rear_axle" type="continuous">
    <parent link="base_link"/>
    <child link="rear_right_wheel_link"/>
    <origin xyz="-1.53 -0.6 0.232" rpy="0 0 0"/>
    <axis xyz="0 -1 0" rpy="0 0 0"/>
      <limit effort="120" velocity="170"/>
</joint>

  <transmission name="rear_right_axle_trans">
    <type>transmission_interface/SimpleTransmission</type>
    <joint name="right_rear_axle">
      <hardwareInterface>hardware_interface/VelocityJointInterface</hardwareInterface>
    </joint>
    <actuator name="rear_right_axle_act">
      <hardwareInterface>hardware_interface/VelocityJointInterface</hardwareInterface>
      <mechanicalReduction>1</mechanicalReduction>
    </actuator>
  </transmission>

    <gazebo reference="rear_right_wheel_link">
      <material>Gazebo/Black</material>
      <turnGravityOff>false</turnGravityOff>
    </gazebo>

  <link name="rear_left_wheel_link">
    <visual>
     <origin xyz="0 0 0" rpy="0 0 0" />
      <geometry>
        <mesh filename="package://autonomousim_description/meshes/wheel.stl"/>
      </geometry>
      <material name="black"/>
    </visual>
    <collision>
     <origin xyz="0 0 0" rpy="0 0 0" />
      <geometry>
        <mesh filename="package://autonomousim_description/meshes/wheel.stl"/>
      </geometry>
      <surface>
        <friction>
          <ode>
            <mu>100</mu>
            <mu2>50</mu2>
          </ode>
        </friction>
      </surface>
    </collision>
    <xacro:wheels_inertia/>
  </link>

  <joint name="left_rear_axle" type="continuous">
    <parent link="base_link"/>
    <child link="rear_left_wheel_link"/>
    <origin xyz="-1.53 0.6 0.232" rpy="0 0 0"/>
    <axis xyz="0 -1 0" rpy="0 0 0"/>
      <limit effort="120" velocity="170"/>
  </joint>   

  <transmission name="rear_left_axle_trans">
    <type>transmission_interface/SimpleTransmission</type>
    <joint name="left_rear_axle">
      <hardwareInterface>hardware_interface/VelocityJointInterface</hardwareInterface>
    </joint>
    <actuator name="rear_left_axle_act">
      <hardwareInterface>hardware_interface/VelocityJointInterface</hardwareInterface>
      <mechanicalReduction>1</mechanicalReduction>
    </actuator>
  </transmission>

    <gazebo reference="rear_left_wheel_link">
      <material>Gazebo/Black</material>
      <turnGravityOff>false</turnGravityOff>
    </gazebo>

    <xacro:imu parent="base_link" prefix="imu">
        <origin xyz="-0.8 0 0.150" rpy="0 0 0"/> 
    </xacro:imu>

    <xacro:sensor_hokuyo_utm30lx  parent="base_link" prefix="lidar" >
        <origin xyz="0.9 0.0 0.150" rpy="0 0 0"/>
    </xacro:sensor_hokuyo_utm30lx> 

    <xacro:zed_camera parent="base_link" prefix="zed">
        <origin xyz="-1.1 0 1" rpy="0 0 0"/> 
    </xacro:zed_camera> 

  <gazebo>
    <plugin name="gazebo_ros_control" filename="libgazebo_ros_control.so">
      <robotNamespace>/ytu_racing</robotNamespace>
      <legacyModeNS>true</legacyModeNS>
    </plugin>
  </gazebo>
</robot>
